Workbook

Sheet Consolidado
B2: Lista de Materiales — Estructuras MT Celsia
B3: Consolidado de 7 estructuras según las 10 categorías funcionales · Fuentes: Celsia-B72C2, B76C, B76C2, B712, C71, C72C, C72E (.xlsx)
B6: Resumen
B7: Estructuras procesadas | D7: 7
B8: Ítems únicos del catálogo | D8: 69
B9: Filas de lista de materiales | D9: 306
B10: Unidades totales (cantidades fijas) | D10: 436
B12: Pos — Estructura de soporte principal
B13: 12 ítems únicos · 29 unidades con cantidad fija
B15: Descripción técnica | C15: Cant. (ud) | D15: Presente en
B16: Poste de concreto, fibra vidrio o metalico 10m /12m /14m /16m × 750kgf /1050kgf /2000kgf/3000kgf /4000kgf | C16: 5 | D16: Todas (7/7)
B17: Brazo tangente tipo L 15kV con grapa prensora y estribo | C17: 3 | D17: Todas (7/7)
B18: Brazo tangente tipo L 38 – 48 kV con grapa prensora y estribo | C18: 2 | D18: Todas (7/7)
B19: Cruceta angular metálica en T autosoportada, 1400 mm | C19: 2 | D19: 5/7: B72C2, B76C, B76C2, C72C, C72E
B20: Soporte para dos aisladores en angulo red compacta (15kV / 35kV) | C20: 6 | D20: 5/7: B72C2, B76C, B76C2, C72C, C72E
B21: Brazo angular tipo C acero red compacta 15kV | C21: 5 | D21: 4/7: B72C2, B76C, B76C2, C72C
B22: Brazo angular tipo C acero red compacta 38kV | C22: 1 | D22: 4/7: B72C2, B76C, B76C2, C72C
B23: Brazo anti-balanceo polimérico red compacta 15 kV | C23: 2 | D23: 4/7: B712, B76C, B76C2, C71
B24: Brazo anti-balanceo polimérico red compacta 38kV | C24: 1 | D24: 4/7: B712, B76C, B76C2, C71
B25: Cruceta metálica retención 600mm 3" X 3" X 1/4" / 2 1/2" x 2 1/2" x 1/4" | C25: 1 | D25: 2/7: B76C, B76C2
B26: Brazo angular tipo E acero red compacta 38kV | C26: 1 | D26: 1/7: C72E
B27: Total Pos | C27: =SUM(Consolidado!C16:C26) -> 29 | D27: 12 ítems
B29: F.Po — Fijación al poste
B30: 1 ítems únicos · 23 unidades con cantidad fija
B32: Descripción técnica | C32: Cant. (ud) | D32: Presente en
B33: Collarín / Abrazadera de 2 o 4 vías para poste (100mm - 4" a Collarin 300mm -12") Diámetro según norma | C33: 23 | D33: Todas (7/7)
B34: Total F.Po | C34: =SUM(Consolidado!C33) -> 23 | D34: 1 ítems
B36: Ais — Aisladores
B37: 7 ítems únicos · 27 unidades con cantidad fija
B39: Descripción técnica | C39: Cant. (ud) | D39: Presente en
B40: Aislador pin polimérico 15 kV ANSI C29.5 clase 55-4 | C40: 6 | D40: 5/7: B72C2, B76C, B76C2, C72C, C72E
B41: Aislador pin polimérico 35 kV ANSI C29.5 clase 55-6 | C41: 6 | D41: 3/7: B72C2, C72C, C72E
B42: Aislador suspensión polimérico 15 kV ANSI C29.13 clase DS-15 clevis-lengüeta | C42: 15 | D42: 2/7: B76C, B76C2
B43: Total Ais | C43: =SUM(Consolidado!C40:C42) -> 27 | D43: 7 ítems
B45: Esp — Espaciamiento de red compacta
B46: 5 ítems únicos · 3 unidades con cantidad fija
B48: Descripción técnica | C48: Cant. (ud) | D48: Presente en
B49: Espaciador poligonal polimérico 15 kV 10 kA cable cubierto | C49: 2 | D49: 1/7: B712
B50: Espaciador poligonal polimérico 38 kV 16 kA cable cubierto (Tipo Pato) | C50: 1 | D50: 1/7: C71
B51: Total Esp | C51: =SUM(Consolidado!C49:C50) -> 3 | D51: 5 ítems
...

Sheet Por Norma
B2: Desglose por norma — qué se pide y en qué norma sale
B3: Cantidad declarada de cada ítem en cada una de las 7 normas · «—» = aparece sin cantidad fija (según diseño) · celda vacía = no aparece en la norma
B6: Unidades con cantidad fija pedidas por norma
B7: B712 | D7: 24
B8: B72C2 | D8: 102
B9: B76C | D9: 75
B10: B76C2 | D10: 149
B11: C71 | D11: 14
B12: C72C | D12: 42
B13: C72E | D13: 30
B14: Total (7 normas) | D14: 436
B16: Pos — Estructura de soporte principal
B17: 12 ítems únicos · 29 unidades con cantidad fija
B19: Descripción técnica | C19: B712 | D19: B72C2 | E19: B76C | F19: B76C2 | G19: C71 | H19: C72C | I19: C72E | J19: Total | K19: Se pide en
B20: Poste de concreto, fibra vidrio o metalico 10m /12m /14m /16m × 750kgf /1050kgf /2000kgf/3000kgf /4000kgf | C20: 1 | D20: — | E20: — | F20: 1 | G20: 1 | H20: 1 | I20: 1 | J20: 5 | K20: 5/7: B712, B76C2, C71, C72C, C72E
B21: Brazo tangente tipo L 15kV con grapa prensora y estribo | C21: 2 | D21: 1 | E21: — | F21: — | G21: — | H21: — | I21: — | J21: 3 | K21: 2/7: B712, B72C2
B22: Brazo tangente tipo L 38 – 48 kV con grapa prensora y estribo | C22: — | D22: — | E22: — | F22: — | G22: 1 | H22: 1 | I22: — | J22: 2 | K22: 2/7: C71, C72C
B23: Cruceta angular metálica en T autosoportada, 1400 mm | D23: — | E23: — | F23: 2 | H23: — | I23: — | J23: 2 | K23: 1/7: B76C2
B24: Soporte para dos aisladores en angulo red compacta (15kV / 35kV) | D24: — | E24: — | F24: 6 | H24: — | I24: — | J24: 6 | K24: 1/7: B76C2
B25: Brazo angular tipo C acero red compacta 15kV | D25: 2 | E25: 1 | F25: 2 | H25: — | J25: 5 | K25: 3/7: B72C2, B76C, B76C2
B26: Brazo angular tipo C acero red compacta 38kV | D26: — | E26: — | F26: — | H26: 1 | J26: 1 | K26: 1/7: C72C
B27: Brazo anti-balanceo polimérico red compacta 15 kV | C27: 2 | E27: — | F27: — | G27: — | J27: 2 | K27: 1/7: B712
B28: Brazo anti-balanceo polimérico red compacta 38kV | C28: — | E28: — | F28: — | G28: 1 | J28: 1 | K28: 1/7: C71
B29: Cruceta metálica retención 600mm 3" X 3" X 1/4" / 2 1/2" x 2 1/2" x 1/4" | E29: 1 | F29: — | J29: 1 | K29: 1/7: B76C
B30: Brazo angular tipo E acero red compacta 15kV | I30: — | J30: 0 | K30: Según diseño
B31: Brazo angular tipo E acero red compacta 38kV | I31: 1 | J31: 1 | K31: 1/7: C72E
B32: Total Pos | C32: =SUM('Por Norma'!C20:C31) -> 5 | D32: =SUM('Por Norma'!D20:D31) -> 3 | E32: =SUM('Por Norma'!E20:E31) -> 2 | F32: =SUM('Por Norma'!F20:F31) -> 11 | G32: =SUM('Por Norma'!G20:G31) -> 3 | H32: =SUM('Por Norma'!H20:H31) -> 3 | I32: =SUM('Por Norma'!I20:I31) -> 2 | J32: =SUM('Por Norma'!J20:J31) -> 29
B34: F.Po — Fijación al poste
B35: 1 ítems únicos · 23 unidades con cantidad fija
B37: Descripción técnica | C37: B712 | D37: B72C2 | E37: B76C | F37: B76C2 | G37: C71 | H37: C72C | I37: C72E | J37: Total | K37: Se pide en
B38: Collarín / Abrazadera de 2 o 4 vías para poste (100mm - 4" a Collarin 300mm -12") Diámetro según norma | C38: 3 | D38: 4 | E38: 3 | F38: 4 | G38: 3 | H38: 4 | I38: 2 | J38: 23 | K38: Todas (7/7)
B39: Total F.Po | C39: =SUM('Por Norma'!C38) -> 3 | D39: =SUM('Por Norma'!D38) -> 4 | E39: =SUM('Por Norma'!E38) -> 3 | F39: =SUM('Por Norma'!F38) -> 4 | G39: =SUM('Por Norma'!G38) -> 3 | H39: =SUM('Por Norma'!H38) -> 4 | I39: =SUM('Por Norma'!I38) -> 2 | J39: =SUM('Por Norma'!J38) -> 23
B41: Ais — Aisladores
B42: 7 ítems únicos · 27 unidades con cantidad fija
B44: Descripción técnica | C44: B712 | D44: B72C2 | E44: B76C | F44: B76C2 | G44: C71 | H44: C72C | I44: C72E | J44: Total | K44: Se pide en
B45: Aislador pin polimérico 15 kV ANSI C29.5 clase 55-4 | D45: 6 | E45: — | F45: — | H45: — | I45: — | J45: 6 | K45: 1/7: B72C2
B46: Aislador pin polimérico 25 kV ANSI C29.5 clase 55-5 | D46: — | E46: — | F46: — | H46: — | I46: — | J46: 0 | K46: Según diseño
B47: Aislador pin polimérico 35 kV ANSI C29.5 clase 55-6 | D47: — | H47: 3 | I47: 3 | J47: 6 | K47: 2/7: C72C, C72E
B48: Aislador pin polimérico 38-48 kV ANSI C29.5 clase 55-6 | E48: — | F48: — | J48: 0 | K48: Según diseño
B49: Aislador suspensión polimérico 15 kV ANSI C29.13 clase DS-15 clevis-lengüeta | E49: 3 | F49: 12 | J49: 15 | K49: 2/7: B76C, B76C2
...

Sheet Estructuras
B2: Estructuras incluidas
B3: Metadatos de los 7 archivos procesados
B6: Archivo | C6: Código | D6: Descripción de la estructura | E6: Tipo | F6: Voltaje | G6: Tipo de estructura (hoja) | H6: Ítems BOM
B7: Celsia-B72C2.xlsx | C7: B72C2 | D7: Estructura ángulos 3° - 30° con herraje en C doble circuito | E7: C2 | F7: 13,2 kV | G7: Aisl. Pin - Tipo C | H7: 47
B8: Celsia-B76C.xlsx | C8: B76C | D8: Terminal sencillo centrado herraje en C | E8: C2 | F8: 13,2 kV | G8: Aisl. Polim - Tipo C | H8: 63
B9: Celsia-B76C2.xlsx | C9: B76C2 | D9: Terminal sencillo doble circuito herraje C lateral | E9: C4 | F9: 13,2 kV | G9: Aisl. Polim - Tipo C | H9: 61
B10: Celsia-B712.xlsx | C10: B712 | D10: Alineación 0° - 3° doble circuito | E10: C4 | F10: 13,2 kV | G10: B. Tangente V.Cxtos - Ais. Pato | H10: 21
B11: Celsia-C71.xlsx | C11: C71 | D11: Estructura Alineacion 0° - 6° Bandera con cruceta de 2400 mm para red aérea | E11: C1 | F11: 34,5 kV | G11: B. Tangente (Antib) - Ais. Pato | H11: 19
B12: Celsia-C72C.xlsx | C12: C72C | D12: Estructura Angulo 3° - 30° con Herraje en C Lateral Circuito Sencillo | E12: C2 | F12: 34,5 kV | G12: Aisl. Pin - Tipo C | H12: 47
B13: Celsia-C72E.xlsx | C13: C72E | D13: Ángulos 3° - 30° herraje E lateral sencillo | E13: C2 | F13: 34,5 kV | G13: Aisl. Pin - Tipo E | H13: 48

Sheet Detalle
B2: Detalle por archivo (306 filas)
B3: Cada fila es un ítem tal como aparece en la lista de materiales de cada estructura
B6: Archivo | C6: Código | D6: Categoría | E6: Descripción técnica | F6: Cant. | G6: Nota de cantidad | H6: Cód. Celsia | I6: Ref. ítem
B7: Celsia-B72C2.xlsx | C7: B72C2 | D7: Pos | E7: Poste de concreto, fibra vidrio o metalico 10m /12m /14m /16m × 750kgf /1050kgf /2000kgf/3000kgf /4000kgf | H7: PM (Ver tablas) | I7: Acorde diseño
B8: Celsia-B72C2.xlsx | C8: B72C2 | D8: F.Po | E8: Collarín / Abrazadera de 2 o 4 vías para poste (100mm - 4" a Collarin 300mm -12") Diámetro según norma | F8: 4 | H8: CXX (2 salidas)
B9: Celsia-B72C2.xlsx | C9: B72C2 | D9: F.Po | E9: Collarín / Abrazadera de 2 o 4 vías para poste (100mm - 4" a Collarin 300mm -12") Diámetro según norma
B10: Celsia-B72C2.xlsx | C10: B72C2 | D10: Pos | E10: Cruceta angular metálica en T autosoportada, 1400 mm
B11: Celsia-B72C2.xlsx | C11: B72C2 | D11: Pos | E11: Brazo tangente tipo L 15kV con grapa prensora y estribo | F11: 1 | H11: H220 | I11: 10006438
B12: Celsia-B72C2.xlsx | C12: B72C2 | D12: Pos | E12: Brazo tangente tipo L 38 – 48 kV con grapa prensora y estribo
B13: Celsia-B72C2.xlsx | C13: B72C2 | D13: Pos | E13: Soporte para dos aisladores en angulo red compacta (15kV / 35kV)
B14: Celsia-B72C2.xlsx | C14: B72C2 | D14: Suj | E14: Grapa Suspension para soporte mensajero red compacta | F14: 2 | H14: UA225 | I14: 10004892
B15: Celsia-B72C2.xlsx | C15: B72C2 | D15: Pos | E15: Brazo angular tipo C acero red compacta 15kV | F15: 2 | H15: H226 | I15: 10006422
B16: Celsia-B72C2.xlsx | C16: B72C2 | D16: Pos | E16: Brazo angular tipo C acero red compacta 38kV
B17: Celsia-B72C2.xlsx | C17: B72C2 | D17: Suj | E17: Estribo para soporte tangencial | H17: RA223 (Ver tablas)
B18: Celsia-B72C2.xlsx | C18: B72C2 | D18: Cond | E18: Cable semiaislado AAC 95 mm 2
B19: Celsia-B72C2.xlsx | C19: B72C2 | D19: Suj | E19: Alambre de amarre de aluminio 4 AWG cubierto con elastómero termoplástico TPE
B20: Celsia-B72C2.xlsx | C20: B72C2 | D20: Cond | E20: Cable mensajero de acero 3/8’’
B21: Celsia-B72C2.xlsx | C21: B72C2 | D21: Esp | E21: Espaciador poligonal polimérico 15 kV 10 kA / 38 kV 16 kA cable cubierto (Tipo Pato) | G21: Cantidad acorde diseño y distancia de instalacion (entre 7 a 9 m)
B22: Celsia-B72C2.xlsx | C22: B72C2 | D22: Ais | E22: Aislador pin polimérico 15 kV ANSI C29.5 clase 55-4 | F22: 6 | H22: DP3 | I22: 10002434
B23: Celsia-B72C2.xlsx | C23: B72C2 | D23: Ais | E23: Aislador pin polimérico 25 kV ANSI C29.5 clase 55-5
B24: Celsia-B72C2.xlsx | C24: B72C2 | D24: Ais | E24: Aislador pin polimérico 35 kV ANSI C29.5 clase 55-6
B25: Celsia-B72C2.xlsx | C25: B72C2 | D25: Suj | E25: Grapa amarre preformado aislado tipo "Z" para red semiaislada. De acuerdo al calibre del conductor (Amarre Preformado) | F25: 6 | H25: RP01
B26: Celsia-B72C2.xlsx | C26: B72C2 | D26: Suj | E26: Grapa preformada aleación de aluminio 2 AWG a 312.8 kcmil 15 kV / 38 kV cable cubierto (Amarre Preformado)
B27: Celsia-B72C2.xlsx | C27: B72C2 | D27: Torni | E27: Eslabón en U 5/8" forjado galvanizado
B28: Celsia-B72C2.xlsx | C28: B72C2 | D28: Torni | E28: Tornillo de máquina hexagonal acero galvanizado 5/8" X 1 1/2"
B29: Celsia-B72C2.xlsx | C29: B72C2 | D29: Torni | E29: Tornillo de máquina hexagonal acero galvanizado 5/8" x 3" | F29: 1 | H29: I9 | I29: 10007363
B30: Celsia-B72C2.xlsx | C30: B72C2 | D30: Torni | E30: Tornillo de máquina hexagonal acero galvanizado1/2" x 3"
B31: Celsia-B72C2.xlsx | C31: B72C2 | D31: Suj | E31: Grapa de retención aluminio tipo pistola (3–4 pernos) 4AWG a 2/0 AWG
B32: Celsia-B72C2.xlsx | C32: B72C2 | D32: Suj | E32: Grapa de retención aluminio tipo pistola (3–4 pernos) 2/0AWG-266.8KCMIL
B33: Celsia-B72C2.xlsx | C33: B72C2 | D33: Torni | E33: Tornillo de máquina hexagonal acero galvanizado 5/8" x 31/2" | F33: 4 | H33: I21 | I33: 10005724
B34: Celsia-B72C2.xlsx | C34: B72C2 | D34: Torni | E34: Perno Espigo corto para aislador tipo pin 10”x1 3/4”x3/4” rosca nailon 1 3/8” cruceta metálica (13,2 kV) | F34: 6 | H34: EP1 | I34: 10005775
B35: Celsia-B72C2.xlsx | C35: B72C2 | D35: Torni | E35: Perno Espigo corto para aislador tipo pin 10”x1 3/4”x3/4” rosca nailon 1 3/8” cruceta metálica (34,5 kV)
B36: Celsia-B72C2.xlsx | C36: B72C2 | D36: Torni | E36: Perno espaciador 15.9 x 305 mm (Esparrago 5/8" x 12")
B37: Celsia-B72C2.xlsx | C37: B72C2 | D37: Torni | E37: Tuercas de ojo alargada acero galv. / Ojos giratorios de Ø15,9 mm (5/8") | F37: 2 | H37: H10 | I37: 10007764
B38: Celsia-B72C2.xlsx | C38: B72C2 | D38: Torni | E38: Tuercas hexagonales de acero 5/8′′ | F38: 24
B39: Celsia-B72C2.xlsx | C39: B72C2 | D39: Torni | E39: Arandelas de presión (Guasa) Galv. Ø15,9 mm (5/8") | F39: 22 | H39: K6 | I39: 10002645
B40: Celsia-B72C2.xlsx | C40: B72C2 | D40: Torni | E40: Arandelas redondas planas de acero Ø15,9 mm (5/8′′) | F40: 22 | H40: K9 | I40: 10002610
B41: Celsia-B72C2.xlsx | C41: B72C2 | D41: P.Ele | E41: Pararrayos polimerico DPS 12 kV 10 kA
B42: Celsia-B72C2.xlsx | C42: B72C2 | D42: P.Ele | E42: Pararrayos polimerico DPS 30 kV 10 kA
B43: Celsia-B72C2.xlsx | C43: B72C2 | D43: Cond | E43: Cable de cobre desnudo #2 AWG
...
